2023-04-12 21:10:36,755 - instabot version: 0.117.0 (bot) - INFO - Instabot version: 0.117.0 Started
2023-04-12 21:10:36,755 - instabot version: 0.117.0 (bot) - DEBUG - Bot imported from /home/xjama/.local/lib/python3.11/site-packages/instabot/bot/bot.py
2023-04-12 21:10:36,756 - instabot version: 0.117.0 (api_login) - INFO - Not yet logged in starting: PRE-LOGIN FLOW!
2023-04-12 21:10:37,486 - instabot version: 0.117.0 (api) - DEBUG - POST to endpoint: accounts/get_prefill_candidates/ returned response: <Response [429]>
2023-04-12 21:10:37,486 - instabot version: 0.117.0 (api) - DEBUG - Responsecode indicates error; response content: b'{"message":"Please wait a few minutes before you try again.","status":"fail"}'
2023-04-12 21:10:37,486 - instabot version: 0.117.0 (api) - ERROR - Request returns 429 error!
2023-04-12 21:10:37,487 - instabot version: 0.117.0 (api) - WARNING - That means 'too many requests'. I'll go to sleep for 5 minutes.
2023-04-12 21:15:38,449 - instabot version: 0.117.0 (api) - DEBUG - POST to endpoint: accounts/get_prefill_candidates/ returned response: <Response [429]>
2023-04-12 21:15:38,449 - instabot version: 0.117.0 (api) - DEBUG - Responsecode indicates error; response content: b'{"message":"Please wait a few minutes before you try again.","status":"fail"}'
2023-04-12 21:15:38,449 - instabot version: 0.117.0 (api) - ERROR - Request returns 429 error!
2023-04-12 21:15:38,449 - instabot version: 0.117.0 (api) - WARNING - That means 'too many requests'. I'll go to sleep for 10 minutes.
2023-04-12 21:25:38,455 - instabot version: 0.117.0 (api) - WARNING - HTTPSConnectionPool(host='i.instagram.com', port=443): Max retries exceeded with url: /api/v1/accounts/get_prefill_candidates/ (Caused by NewConnectionError('<urllib3.connection.HTTPSConnection object at 0x7f15b0f52810>: Failed to establish a new connection: [Errno -3] Temporary failure in name resolution'))
2023-04-12 21:25:38,459 - instabot version: 0.117.0 (api) - WARNING - HTTPSConnectionPool(host='i.instagram.com', port=443): Max retries exceeded with url: /api/v1/qe/sync/ (Caused by NewConnectionError('<urllib3.connection.HTTPSConnection object at 0x7f15b0f5cb10>: Failed to establish a new connection: [Errno -3] Temporary failure in name resolution'))
2023-04-12 21:25:38,461 - instabot version: 0.117.0 (api) - WARNING - HTTPSConnectionPool(host='i.instagram.com', port=443): Max retries exceeded with url: /api/v1/launcher/sync/ (Caused by NewConnectionError('<urllib3.connection.HTTPSConnection object at 0x7f15b0f3df10>: Failed to establish a new connection: [Errno -3] Temporary failure in name resolution'))
2023-04-12 21:25:38,463 - instabot version: 0.117.0 (api) - WARNING - HTTPSConnectionPool(host='i.instagram.com', port=443): Max retries exceeded with url: /api/v1/accounts/contact_point_prefill/ (Caused by NewConnectionError('<urllib3.connection.HTTPSConnection object at 0x7f15b0f5d110>: Failed to establish a new connection: [Errno -3] Temporary failure in name resolution'))
